<robot xmlns:xacro="http://ros.org/wiki/xacro" name="robot_gripper">

  <xacro:macro name="gripper" params="prefix reflect">
    <joint name="${prefix}_gripper_joint" type="revolute">
      <axis xyz="0 0 ${reflect}"/>
      <limit effort="1000.0" lower="0.0" upper="0.548" velocity="0.5"/>
      <origin rpy="0 0 0" xyz="${polelen} ${reflect*0.01} 0"/>
      <parent link="gripper_pole"/>
      <child link="${prefix}_gripper"/>
    </joint>
    <link name="${prefix}_gripper">
      <visual>
        <origin rpy="${(reflect-1)/2*pi} 0 0" xyz="0 0 0"/>
        <geometry>
          <mesh filename="package://project_one/meshes/l_finger.dae"/>
        </geometry>
      </visual>
      <collision>
        <geometry>
          <mesh filename="package://project_one/meshes/l_finger.dae"/>
        </geometry>
        <origin rpy="${(reflect-1)/2*pi} 0 0" xyz="0 0 0"/>
      </collision>
      <xacro:default_inertial mass="0.05"/>
    </link>
	<transmission name="${prefix}_gripper_trans">
      <type>transmission_interface/SimpleTransmission</type>
      <actuator name="${prefix}_gripper_motor">
        <mechanicalReduction>1</mechanicalReduction>
      </actuator>
      <joint name="${prefix}_gripper_joint">
        <hardwareInterface>PositionJointInterface</hardwareInterface>
      </joint>
    </transmission>

    <joint name="${prefix}_tip_joint" type="fixed">
      <parent link="${prefix}_gripper"/>
      <child link="${prefix}_tip"/>
    </joint>
    <link name="${prefix}_tip">
      <visual>
        <origin rpy="${(reflect-1)/2*pi} 0 0" xyz="0.09137 0.00495 0"/>
        <geometry>
          <mesh filename="package://project_one/meshes/l_finger_tip.dae"/>
        </geometry>
      </visual>
      <collision>
        <geometry>
          <mesh filename="package://project_one/meshes/l_finger_tip.dae"/>
        </geometry>
        <origin rpy="${(reflect-1)/2*pi} 0 0" xyz="0.09137 0.00495 0"/>
      </collision>
      <xacro:default_inertial mass="0.05"/>
    </link>
  </xacro:macro>

</robot>
